# def xor_encrypt_decrypt(data, key):
#   """
#   Encrypts or decrypts data using XOR encryption with a given key.

#   Args:
#     data: The data to encrypt or decrypt (bytes).
#     key: The key to use for encryption or decryption (bytes).

#   Returns:
#     The encrypted or decrypted data (bytes).
#   """
#   return bytes(a ^ b for a, b in zip(data, key * len(data)))

# # Example usage
# data = b"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"
# key = b"kabirdas"

# encrypted_data = xor_encrypt_decrypt(data, key)
# decrypted_data = xor_encrypt_decrypt(encrypted_data, key)

# print("Original data:", data)
# print("Encrypted data:", encrypted_data)
# print("Decrypted data:", decrypted_data)


# import os
# from dotenv import load_dotenv

# load_dotenv()

# openai_api_key = os.getenv("OPENAI_API_KEY")
# print(openai_api_key)

string = """
"\"{\"error_type\": \"<class 'openai.APIConnectionError'>\", \"error_message\": \"Connection error.\", \"error_traceback\": \"Traceback (most recent call last):\\n  File \\\"/usr/local/lib/python3.11/dist-packages/httpcore/_exceptions.py\\\", line 10, in map_exceptions\\n    yield\\n  File \\\"/usr/local/lib/python3.11/dist-packages/httpcore/_sync/http11.py\\\", line 142, in _send_request_headers\\n    event = h11.Request(\\n            ^^^^^^^^^^^^\\n  File \\\"/usr/local/lib/python3.11/dist-packages/h11/_events.py\\\", line 96, in __init__\\n    self, \\\"headers\\\", normalize_and_validate(headers, _parsed=_parsed)\\n                     ^^^^^^^^^^^^^^^^^^^^^^^^^^^^^^^^^^^^^^^^^^^^^^^^\\n  File \\\"/usr/local/lib/python3.11/dist-packages/h11/_headers.py\\\", line 164, in normalize_and_validate\\n    validate(_field_value_re, value, \\\"Illegal header value {!r}\\\", value)\\n  File \\\"/usr/local/lib/python3.11/dist-packages/h11/_util.py\\\", line 91, in validate\\n    raise LocalProtocolError(msg)\\nh11._util.LocalProtocolError: Illegal header value b'Bearer '\\n\\nThe above exception was the direct cause of the following exception:\\n\\nTraceback (most recent call last):\\n  File \\\"/usr/local/lib/python3.11/dist-packages/httpx/_transports/default.py\\\", line 67, in map_httpcore_exceptions\\n    yield\\n  File \\\"/usr/local/lib/python3.11/dist-packages/httpx/_transports/default.py\\\", line 231, in handle_request\\n    resp = self._pool.handle_request(req)\\n           ^^^^^^^^^^^^^^^^^^^^^^^^^^^^^^\\n  File \\\"/usr/local/lib/python3.11/dist-packages/httpcore/_sync/connection_pool.py\\\", line 268, in handle_request\\n    raise exc\\n  File \\\"/usr/local/lib/python3.11/dist-packages/httpcore/_sync/connection_pool.py\\\", line 251, in handle_request\\n    response = connection.handle_request(request)\\n               ^^^^^^^^^^^^^^^^^^^^^^^^^^^^^^^^^^\\n  File \\\"/usr/local/lib/python3.11/dist-packages/httpcore/_sync/connection.py\\\", line 103, in handle_request\\n    return self._connection.handle_request(request)\\n           ^^^^^^^^^^^^^^^^^^^^^^^^^^^^^^^^^^^^^^^^\\n  File \\\"/usr/local/lib/python3.11/dist-packages/httpcore/_sync/http11.py\\\", line 133, in handle_request\\n    raise exc\\n  File \\\"/usr/local/lib/python3.11/dist-packages/httpcore/_sync/http11.py\\\", line 92, in handle_request\\n    self._send_request_headers(**kwargs)\\n  File \\\"/usr/local/lib/python3.11/dist-packages/httpcore/_sync/http11.py\\\", line 141, in _send_request_headers\\n    with map_exceptions({h11.LocalProtocolError: LocalProtocolError}):\\n  File \\\"/usr/lib/python3.11/contextlib.py\\\", line 155, in __exit__\\n    self.gen.throw(typ, value, traceback)\\n  File \\\"/usr/local/lib/python3.11/dist-packages/httpcore/_exceptions.py\\\", line 14, in map_exceptions\\n    raise to_exc(exc) from exc\\nhttpcore.LocalProtocolError: Illegal header value b'Bearer '\\n\\nThe above exception was the direct cause of the following exception:\\n\\nTraceback (most recent call last):\\n  File \\\"/usr/local/lib/python3.11/dist-packages/openai/_base_client.py\\\", line 918, in _request\\n    response = self._client.send(\\n               ^^^^^^^^^^^^^^^^^^\\n  File \\\"/usr/local/lib/python3.11/dist-packages/httpx/_client.py\\\", line 915, in send\\n    response = self._send_handling_auth(\\n               ^^^^^^^^^^^^^^^^^^^^^^^^^\\n  File \\\"/usr/local/lib/python3.11/dist-packages/httpx/_client.py\\\", line 943, in _send_handling_auth\\n    response = self._send_handling_redirects(\\n               ^^^^^^^^^^^^^^^^^^^^^^^^^^^^^^\\n  File \\\"/usr/local/lib/python3.11/dist-packages/httpx/_client.py\\\", line 980, in _send_handling_redirects\\n    response = self._send_single_request(request)\\n               ^^^^^^^^^^^^^^^^^^^^^^^^^^^^^^^^^^\\n  File \\\"/usr/local/lib/python3.11/dist-packages/httpx/_client.py\\\", line 1016, in _send_single_request\\n    response = transport.handle_request(request)\\n               ^^^^^^^^^^^^^^^^^^^^^^^^^^^^^^^^^\\n  File \\\"/usr/local/lib/python3.11/dist-packages/httpx/_transports/default.py\\\", line 230, in handle_request\\n    with map_httpcore_exceptions():\\n  File \\\"/usr/lib/python3.11/contextlib.py\\\", line 155, in __exit__\\n    self.gen.throw(typ, value, traceback)\\n  File \\\"/usr/local/lib/python3.11/dist-packages/httpx/_transports/default.py\\\", line 84, in map_httpcore_exceptions\\n    raise mapped_exc(message) from exc\\nhttpx.LocalProtocolError: Illegal header value b'Bearer '\\n\\nDuring handling of the above exception, another exception occurred:\\n\\nTraceback (most recent call last):\\n  File \\\"/usr/local/lib/python3.11/dist-packages/httpcore/_exceptions.py\\\", line 10, in map_exceptions\\n    yield\\n  File \\\"/usr/local/lib/python3.11/dist-packages/httpcore/_sync/http11.py\\\", line 142, in _send_request_headers\\n    event = h11.Request(\\n            ^^^^^^^^^^^^\\n  File \\\"/usr/local/lib/python3.11/dist-packages/h11/_events.py\\\", line 96, in __init__\\n    self, \\\"headers\\\", normalize_and_validate(headers, _parsed=_parsed)\\n                     ^^^^^^^^^^^^^^^^^^^^^^^^^^^^^^^^^^^^^^^^^^^^^^^^\\n  File \\\"/usr/local/lib/python3.11/dist-packages/h11/_headers.py\\\", line 164, in normalize_and_validate\\n    validate(_field_value_re, value, \\\"Illegal header value {!r}\\\", value)\\n  File \\\"/usr/local/lib/python3.11/dist-packages/h11/_util.py\\\", line 91, in validate\\n    raise LocalProtocolError(msg)\\nh11._util.LocalProtocolError: Illegal header value b'Bearer '\\n\\nThe above exception was the direct cause of the following exception:\\n\\nTraceback (most recent call last):\\n  File \\\"/usr/local/lib/python3.11/dist-packages/httpx/_transports/default.py\\\", line 67, in map_httpcore_exceptions\\n    yield\\n  File \\\"/usr/local/lib/python3.11/dist-packages/httpx/_transports/default.py\\\", line 231, in handle_request\\n    resp = self._pool.handle_request(req)\\n           ^^^^^^^^^^^^^^^^^^^^^^^^^^^^^^\\n  File \\\"/usr/local/lib/python3.11/dist-packages/httpcore/_sync/connection_pool.py\\\", line 268, in handle_request\\n    raise exc\\n  File \\\"/usr/local/lib/python3.11/dist-packages/httpcore/_sync/connection_pool.py\\\", line 251, in handle_request\\n    response = connection.handle_request(request)\\n               ^^^^^^^^^^^^^^^^^^^^^^^^^^^^^^^^^^\\n  File \\\"/usr/local/lib/python3.11/dist-packages/httpcore/_sync/connection.py\\\", line 103, in handle_request\\n    return self._connection.handle_request(request)\\n           ^^^^^^^^^^^^^^^^^^^^^^^^^^^^^^^^^^^^^^^^\\n  File \\\"/usr/local/lib/python3.11/dist-packages/httpcore/_sync/http11.py\\\", line 133, in handle_request\\n    raise exc\\n  File \\\"/usr/local/lib/python3.11/dist-packages/httpcore/_sync/http11.py\\\", line 92, in handle_request\\n    self._send_request_headers(**kwargs)\\n  File \\\"/usr/local/lib/python3.11/dist-packages/httpcore/_sync/http11.py\\\", line 141, in _send_request_headers\\n    with map_exceptions({h11.LocalProtocolError: LocalProtocolError}):\\n  File \\\"/usr/lib/python3.11/contextlib.py\\\", line 155, in __exit__\\n    self.gen.throw(typ, value, traceback)\\n  File \\\"/usr/local/lib/python3.11/dist-packages/httpcore/_exceptions.py\\\", line 14, in map_exceptions\\n    raise to_exc(exc) from exc\\nhttpcore.LocalProtocolError: Illegal header value b'Bearer '\\n\\nThe above exception was the direct cause of the following exception:\\n\\nTraceback (most recent call last):\\n  File \\\"/usr/local/lib/python3.11/dist-packages/openai/_base_client.py\\\", line 918, in _request\\n    response = self._client.send(\\n               ^^^^^^^^^^^^^^^^^^\\n  File \\\"/usr/local/lib/python3.11/dist-packages/httpx/_client.py\\\", line 915, in send\\n    response = self._send_handling_auth(\\n               ^^^^^^^^^^^^^^^^^^^^^^^^^\\n  File \\\"/usr/local/lib/python3.11/dist-packages/httpx/_client.py\\\", line 943, in _send_handling_auth\\n    response = self._send_handling_redirects(\\n               ^^^^^^^^^^^^^^^^^^^^^^^^^^^^^^\\n  File \\\"/usr/local/lib/python3.11/dist-packages/httpx/_client.py\\\", line 980, in _send_handling_redirects\\n    response = self._send_single_request(request)\\n               ^^^^^^^^^^^^^^^^^^^^^^^^^^^^^^^^^^\\n  File \\\"/usr/local/lib/python3.11/dist-packages/httpx/_client.py\\\", line 1016, in _send_single_request\\n    response = transport.handle_request(request)\\n               ^^^^^^^^^^^^^^^^^^^^^^^^^^^^^^^^^\\n  File \\\"/usr/local/lib/python3.11/dist-packages/httpx/_transports/default.py\\\", line 230, in handle_request\\n    with map_httpcore_exceptions():\\n  File \\\"/usr/lib/python3.11/contextlib.py\\\", line 155, in __exit__\\n    self.gen.throw(typ, value, traceback)\\n  File \\\"/usr/local/lib/python3.11/dist-packages/httpx/_transports/default.py\\\", line 84, in map_httpcore_exceptions\\n    raise mapped_exc(message) from exc\\nhttpx.LocalProtocolError: Illegal header value b'Bearer '\\n\\nDuring handling of the above exception, another exception occurred:\\n\\nTraceback (most recent call last):\\n  File \\\"/usr/local/lib/python3.11/dist-packages/httpcore/_exceptions.py\\\", line 10, in map_exceptions\\n    yield\\n  File \\\"/usr/local/lib/python3.11/dist-packages/httpcore/_sync/http11.py\\\", line 142, in _send_request_headers\\n    event = h11.Request(\\n            ^^^^^^^^^^^^\\n  File \\\"/usr/local/lib/python3.11/dist-packages/h11/_events.py\\\", line 96, in __init__\\n    self, \\\"headers\\\", normalize_and_validate(headers, _parsed=_parsed)\\n                     ^^^^^^^^^^^^^^^^^^^^^^^^^^^^^^^^^^^^^^^^^^^^^^^^\\n  File \\\"/usr/local/lib/python3.11/dist-packages/h11/_headers.py\\\", line 164, in normalize_and_validate\\n    validate(_field_value_re, value, \\\"Illegal header value {!r}\\\", value)\\n  File \\\"/usr/local/lib/python3.11/dist-packages/h11/_util.py\\\", line 91, in validate\\n    raise LocalProtocolError(msg)\\nh11._util.LocalProtocolError: Illegal header value b'Bearer '\\n\\nThe above exception was the direct cause of the following exception:\\n\\nTraceback (most recent call last):\\n  File \\\"/usr/local/lib/python3.11/dist-packages/httpx/_transports/default.py\\\", line 67, in map_httpcore_exceptions\\n    yield\\n  File \\\"/usr/local/lib/python3.11/dist-packages/httpx/_transports/default.py\\\", line 231, in handle_request\\n    resp = self._pool.handle_request(req)\\n           ^^^^^^^^^^^^^^^^^^^^^^^^^^^^^^\\n  File \\\"/usr/local/lib/python3.11/dist-packages/httpcore/_sync/connection_pool.py\\\", line 268, in handle_request\\n    raise exc\\n  File \\\"/usr/local/lib/python3.11/dist-packages/httpcore/_sync/connection_pool.py\\\", line 251, in handle_request\\n    response = connection.handle_request(request)\\n               ^^^^^^^^^^^^^^^^^^^^^^^^^^^^^^^^^^\\n  File \\\"/usr/local/lib/python3.11/dist-packages/httpcore/_sync/connection.py\\\", line 103, in handle_request\\n    return self._connection.handle_request(request)\\n           ^^^^^^^^^^^^^^^^^^^^^^^^^^^^^^^^^^^^^^^^\\n  File \\\"/usr/local/lib/python3.11/dist-packages/httpcore/_sync/http11.py\\\", line 133, in handle_request\\n    raise exc\\n  File \\\"/usr/local/lib/python3.11/dist-packages/httpcore/_sync/http11.py\\\", line 92, in handle_request\\n    self._send_request_headers(**kwargs)\\n  File \\\"/usr/local/lib/python3.11/dist-packages/httpcore/_sync/http11.py\\\", line 141, in _send_request_headers\\n    with map_exceptions({h11.LocalProtocolError: LocalProtocolError}):\\n  File \\\"/usr/lib/python3.11/contextlib.py\\\", line 155, in __exit__\\n    self.gen.throw(typ, value, traceback)\\n  File \\\"/usr/local/lib/python3.11/dist-packages/httpcore/_exceptions.py\\\", line 14, in map_exceptions\\n    raise to_exc(exc) from exc\\nhttpcore.LocalProtocolError: Illegal header value b'Bearer '\\n\\nThe above exception was the direct cause of the following exception:\\n\\nTraceback (most recent call last):\\n  File \\\"/usr/local/lib/python3.11/dist-packages/openai/_base_client.py\\\", line 918, in _request\\n    response = self._client.send(\\n               ^^^^^^^^^^^^^^^^^^\\n  File \\\"/usr/local/lib/python3.11/dist-packages/httpx/_client.py\\\", line 915, in send\\n    response = self._send_handling_auth(\\n               ^^^^^^^^^^^^^^^^^^^^^^^^^\\n  File \\\"/usr/local/lib/python3.11/dist-packages/httpx/_client.py\\\", line 943, in _send_handling_auth\\n    response = self._send_handling_redirects(\\n               ^^^^^^^^^^^^^^^^^^^^^^^^^^^^^^\\n  File \\\"/usr/local/lib/python3.11/dist-packages/httpx/_client.py\\\", line 980, in _send_handling_redirects\\n    response = self._send_single_request(request)\\n               ^^^^^^^^^^^^^^^^^^^^^^^^^^^^^^^^^^\\n  File \\\"/usr/local/lib/python3.11/dist-packages/httpx/_client.py\\\", line 1016, in _send_single_request\\n    response = transport.handle_request(request)\\n               ^^^^^^^^^^^^^^^^^^^^^^^^^^^^^^^^^\\n  File \\\"/usr/local/lib/python3.11/dist-packages/httpx/_transports/default.py\\\", line 230, in handle_request\\n    with map_httpcore_exceptions():\\n  File \\\"/usr/lib/python3.11/contextlib.py\\\", line 155, in __exit__\\n    self.gen.throw(typ, value, traceback)\\n  File \\\"/usr/local/lib/python3.11/dist-packages/httpx/_transports/default.py\\\", line 84, in map_httpcore_exceptions\\n    raise mapped_exc(message) from exc\\nhttpx.LocalProtocolError: Illegal header value b'Bearer '\\n\\nDuring handling of the above exception, another exception occurred:\\n\\nTraceback (most recent call last):\\n  File \\\"/usr/local/lib/python3.11/dist-packages/httpcore/_exceptions.py\\\", line 10, in map_exceptions\\n    yield\\n  File \\\"/usr/local/lib/python3.11/dist-packages/httpcore/_sync/http11.py\\\", line 142, in _send_request_headers\\n    event = h11.Request(\\n            ^^^^^^^^^^^^\\n  File \\\"/usr/local/lib/python3.11/dist-packages/h11/_events.py\\\", line 96, in __init__\\n    self, \\\"headers\\\", normalize_and_validate(headers, _parsed=_parsed)\\n                     ^^^^^^^^^^^^^^^^^^^^^^^^^^^^^^^^^^^^^^^^^^^^^^^^\\n  File \\\"/usr/local/lib/python3.11/dist-packages/h11/_headers.py\\\", line 164, in normalize_and_validate\\n    validate(_field_value_re, value, \\\"Illegal header value {!r}\\\", value)\\n  File \\\"/usr/local/lib/python3.11/dist-packages/h11/_util.py\\\", line 91, in validate\\n    raise LocalProtocolError(msg)\\nh11._util.LocalProtocolError: Illegal header value b'Bearer '\\n\\nThe above exception was the direct cause of the following exception:\\n\\nTraceback (most recent call last):\\n  File \\\"/usr/local/lib/python3.11/dist-packages/httpx/_transports/default.py\\\", line 67, in map_httpcore_exceptions\\n    yield\\n  File \\\"/usr/local/lib/python3.11/dist-packages/httpx/_transports/default.py\\\", line 231, in handle_request\\n    resp = self._pool.handle_request(req)\\n           ^^^^^^^^^^^^^^^^^^^^^^^^^^^^^^\\n  File \\\"/usr/local/lib/python3.11/dist-packages/httpcore/_sync/connection_pool.py\\\", line 268, in handle_request\\n    raise exc\\n  File \\\"/usr/local/lib/python3.11/dist-packages/httpcore/_sync/connection_pool.py\\\", line 251, in handle_request\\n    response = connection.handle_request(request)\\n               ^^^^^^^^^^^^^^^^^^^^^^^^^^^^^^^^^^\\n  File \\\"/usr/local/lib/python3.11/dist-packages/httpcore/_sync/connection.py\\\", line 103, in handle_request\\n    return self._connection.handle_request(request)\\n           ^^^^^^^^^^^^^^^^^^^^^^^^^^^^^^^^^^^^^^^^\\n  File \\\"/usr/local/lib/python3.11/dist-packages/httpcore/_sync/http11.py\\\", line 133, in handle_request\\n    raise exc\\n  File \\\"/usr/local/lib/python3.11/dist-packages/httpcore/_sync/http11.py\\\", line 92, in handle_request\\n    self._send_request_headers(**kwargs)\\n  File \\\"/usr/local/lib/python3.11/dist-packages/httpcore/_sync/http11.py\\\", line 141, in _send_request_headers\\n    with map_exceptions({h11.LocalProtocolError: LocalProtocolError}):\\n  File \\\"/usr/lib/python3.11/contextlib.py\\\", line 155, in __exit__\\n    self.gen.throw(typ, value, traceback)\\n  File \\\"/usr/local/lib/python3.11/dist-packages/httpcore/_exceptions.py\\\", line 14, in map_exceptions\\n    raise to_exc(exc) from exc\\nhttpcore.LocalProtocolError: Illegal header value b'Bearer '\\n\\nThe above exception was the direct cause of the following exception:\\n\\nTraceback (most recent call last):\\n  File \\\"/usr/local/lib/python3.11/dist-packages/openai/_base_client.py\\\", line 918, in _request\\n    response = self._client.send(\\n               ^^^^^^^^^^^^^^^^^^\\n  File \\\"/usr/local/lib/python3.11/dist-packages/httpx/_client.py\\\", line 915, in send\\n    response = self._send_handling_auth(\\n               ^^^^^^^^^^^^^^^^^^^^^^^^^\\n  File \\\"/usr/local/lib/python3.11/dist-packages/httpx/_client.py\\\", line 943, in _send_handling_auth\\n    response = self._send_handling_redirects(\\n               ^^^^^^^^^^^^^^^^^^^^^^^^^^^^^^\\n  File \\\"/usr/local/lib/python3.11/dist-packages/httpx/_client.py\\\", line 980, in _send_handling_redirects\\n    response = self._send_single_request(request)\\n               ^^^^^^^^^^^^^^^^^^^^^^^^^^^^^^^^^^\\n  File \\\"/usr/local/lib/python3.11/dist-packages/httpx/_client.py\\\", line 1016, in _send_single_request\\n    response = transport.handle_request(request)\\n               ^^^^^^^^^^^^^^^^^^^^^^^^^^^^^^^^^\\n  File \\\"/usr/local/lib/python3.11/dist-packages/httpx/_transports/default.py\\\", line 230, in handle_request\\n    with map_httpcore_exceptions():\\n  File \\\"/usr/lib/python3.11/contextlib.py\\\", line 155, in __exit__\\n    self.gen.throw(typ, value, traceback)\\n  File \\\"/usr/local/lib/python3.11/dist-packages/httpx/_transports/default.py\\\", line 84, in map_httpcore_exceptions\\n    raise mapped_exc(message) from exc\\nhttpx.LocalProtocolError: Illegal header value b'Bearer '\\n\\nThe above exception was the direct cause of the following exception:\\n\\nTraceback (most recent call last):\\n  File \\\"/usr/local/lib/python3.11/dist-packages/runpod/serverless/modules/rp_job.py\\\", line 134, in run_job\\n    handler_return = handler(job)\\n                     ^^^^^^^^^^^^\\n  File \\\"/handler.py\\\", line 83, in handler\\n    response = query_engine.query(query)\\n               ^^^^^^^^^^^^^^^^^^^^^^^^^\\n  File \\\"/usr/local/lib/python3.11/dist-packages/llama_index/core/base_query_engine.py\\\", line 40, in query\\n    return self._query(str_or_query_bundle)\\n           ^^^^^^^^^^^^^^^^^^^^^^^^^^^^^^^^\\n  File \\\"/usr/local/lib/python3.11/dist-packages/llama_index/query_engine/retriever_query_engine.py\\\", line 172, in _query\\n    response = self._response_synthesizer.synthesize(\\n               ^^^^^^^^^^^^^^^^^^^^^^^^^^^^^^^^^^^^^^\\n  File \\\"/usr/local/lib/python3.11/dist-packages/llama_index/response_synthesizers/base.py\\\", line 168, in synthesize\\n    response_str = self.get_response(\\n                   ^^^^^^^^^^^^^^^^^^\\n  File \\\"/usr/local/lib/python3.11/dist-packages/llama_index/response_synthesizers/compact_and_refine.py\\\", line 38, in get_response\\n    return super().get_response(\\n           ^^^^^^^^^^^^^^^^^^^^^\\n  File \\\"/usr/local/lib/python3.11/dist-packages/llama_index/response_synthesizers/refine.py\\\", line 146, in get_response\\n    response = self._give_response_single(\\n               ^^^^^^^^^^^^^^^^^^^^^^^^^^^\\n  File \\\"/usr/local/lib/python3.11/dist-packages/llama_index/response_synthesizers/refine.py\\\", line 202, in _give_response_single\\n    program(\\n  File \\\"/usr/local/lib/python3.11/dist-packages/llama_index/response_synthesizers/refine.py\\\", line 64, in __call__\\n    answer = self._llm.predict(\\n             ^^^^^^^^^^^^^^^^^^\\n  File \\\"/usr/local/lib/python3.11/dist-packages/llama_index/llms/llm.py\\\", line 239, in predict\\n    chat_response = self.chat(messages)\\n                    ^^^^^^^^^^^^^^^^^^^\\n  File \\\"/usr/local/lib/python3.11/dist-packages/llama_index/llms/base.py\\\", line 100, in wrapped_llm_chat\\n    f_return_val = f(_self, messages, **kwargs)\\n                   ^^^^^^^^^^^^^^^^^^^^^^^^^^^^\\n  File \\\"/usr/local/lib/python3.11/dist-packages/llama_index/llms/openai.py\\\", line 237, in chat\\n    return chat_fn(messages, **kwargs)\\n           ^^^^^^^^^^^^^^^^^^^^^^^^^^^\\n  File \\\"/usr/local/lib/python3.11/dist-packages/llama_index/llms/openai.py\\\", line 296, in _chat\\n    response = client.chat.completions.create(\\n               ^^^^^^^^^^^^^^^^^^^^^^^^^^^^^^^\\n  File \\\"/usr/local/lib/python3.11/dist-packages/openai/_utils/_utils.py\\\", line 271, in wrapper\\n    return func(*args, **kwargs)\\n           ^^^^^^^^^^^^^^^^^^^^^\\n  File \\\"/usr/local/lib/python3.11/dist-packages/openai/resources/chat/completions.py\\\", line 659, in create\\n    return self._post(\\n           ^^^^^^^^^^^\\n  File \\\"/usr/local/lib/python3.11/dist-packages/openai/_base_client.py\\\", line 1200, in post\\n    return cast(ResponseT, self.request(cast_to, opts, stream=stream, stream_cls=stream_cls))\\n                           ^^^^^^^^^^^^^^^^^^^^^^^^^^^^^^^^^^^^^^^^^^^^^^^^^^^^^^^^^^^^^^^^^\\n  File \\\"/usr/local/lib/python3.11/dist-packages/openai/_base_client.py\\\", line 889, in request\\n    return self._request(\\n           ^^^^^^^^^^^^^^\\n  File \\\"/usr/local/lib/python3.11/dist-packages/openai/_base_client.py\\\", line 942, in _request\\n    return self._retry_request(\\n           ^^^^^^^^^^^^^^^^^^^^\\n  File \\\"/usr/local/lib/python3.11/dist-packages/openai/_base_client.py\\\", line 1013, in _retry_request\\n    return self._request(\\n           ^^^^^^^^^^^^^^\\n  File \\\"/usr/local/lib/python3.11/dist-packages/openai/_base_client.py\\\", line 942, in _request\\n    return self._retry_request(\\n           ^^^^^^^^^^^^^^^^^^^^\\n  File \\\"/usr/local/lib/python3.11/dist-packages/openai/_base_client.py\\\", line 1013, in _retry_request\\n    return self._request(\\n           ^^^^^^^^^^^^^^\\n  File \\\"/usr/local/lib/python3.11/dist-packages/openai/_base_client.py\\\", line 942, in _request\\n    return self._retry_request(\\n           ^^^^^^^^^^^^^^^^^^^^\\n  File \\\"/usr/local/lib/python3.11/dist-packages/openai/_base_client.py\\\", line 1013, in _retry_request\\n    return self._request(\\n           ^^^^^^^^^^^^^^\\n  File \\\"/usr/local/lib/python3.11/dist-packages/openai/_base_client.py\\\", line 952, in _request\\n    raise APIConnectionError(request=request) from err\\nopenai.APIConnectionError: Connection error.\\n\", \"hostname\": \"tycijy4h2he1ty-64410bab\", \"worker_id\": \"tycijy4h2he1ty\", \"runpod_version\": \"1.5.2\"}"
"""
print(string)